Workbook

Sheet Project Data
A1: Project Name | B1: TaskOrbit Conversational Agent
A3: Online team meeting | B3: https://fau.zoom-x.de/j/65288966243?pwd=DnF4jxSAfJugyMmynzjE1BaaFprRbi.1
A5: Production system (if any) | B5: GCP
A6: Test system (if any) | B6: None
A8: GitHub repository | B8: https://github.com/amosproj/amos2026ss04-taskorbit-conversational-agent
A9: GitHub feature board | B9: https://github.com/orgs/amosproj/projects/100/views/2
A10: GitHub imp-squared backlog | B10: https://github.com/orgs/amosproj/projects/104/views/1
A12: Position of T-shirt logo | B12: Upper Torso Center Large
A13: Link to logo for black T-shirt | B13: https://github.com/amosproj/amos2026ss04-taskorbit-conversational-agent/blob/feature/team-logo-design/Deliverables/sprint-01/team-logo.png
A14: Link to logo for white T-shirt | B14: https://github.com/amosproj/amos2026ss04-taskorbit-conversational-agent/blob/feature/team-logo-design/Deliverables/sprint-01/team-logo.png
A16: Additional materials | B16: https://discord.gg/usXpc5ab
A18: Team maling list | B18: oss-amos-proj4@lists.fau.de

Sheet Project Team
A1: Last Name | B1: First Name | C1: GitHub User Name | D1: Email Address
A2: Fatima | B2: Qiblatain | C2: qiblatainf | D2: qiblatain.fatima@fau.de
A3: Huy | B3: Christoph | C3: Perimora | D3: christoph.huy@campus.tu-berlin.de
A4: Raza | B4: Asad | C4: asadraza17 | D4: asad.raza@fau.de
A5: Jokiel | B5: Rene | C5: BelmontR | D5: rene.jokiel@fau.de
A6: Mosler | B6: Carl | C6: Caerum5 | D6: carl.mosler@tu-berlin.de
A7: Vineesh | B7: Koppay | C7: K-Vineesh | D7: vineesh.koppay@fau.de
A8: Moeez | B8: Abdul | C8: abdulmoeez1225 | D8: abdul.moeez@fau.de
A9: Thakur | B9: Shikhar | C9: shikharthakur2404` | D9: shikhar.thakur@fau.de
A10: Dhruvin | B10: Vekariya | C10: djv03 | D10: dhruvin.vekariya@fau.de
A11: Shameti | B11: Endri | C11: 1Endri | D11: endri.shameti@fau.de

Sheet Role Assignments
C1: Product Owner
A2: # | B2: Meeting Day | C2: Review | D2: Planning | E2: Software Developer | F2: Release Manager | G2: Scrum Master | H2: Comment
A3: 1 | B3: 46127 | D3: Carl | E3: Everyone else | F3: N/A | G3: Rene
A4: 2 | B4: =B3+7 -> 46134 | C4: Carl | D4: Christoph | F4: Endri Shameti | G4: Rene
A5: 3 | B5: =B4+7 -> 46141 | C5: Christoph | D5: Carl | F5: Dhruvin | G5: Rene
A6: 4 | B6: =B5+7 -> 46148 | C6: Carl | D6: Christoph | F6: Qiblatain | G6: Rene
A7: 5 | B7: =B6+7 -> 46155 | C7: Christoph | D7: Carl | F7: Vineesh Koppay | G7: Rene
A8: 6 | B8: =B7+7 -> 46162 | C8: Carl | D8: Christoph | F8: Asad Raza | G8: Rene
A9: 7 | B9: =B8+7 -> 46169 | C9: Christoph | D9: Carl | F9: Abdul Moeez | G9: Rene | H9: Mid-term due
A10: 8 | B10: =B9+7 -> 46176 | C10: Carl | D10: Christoph | F10: Shikhar | G10: Rene
A11: 9 | B11: =B10+7 -> 46183 | C11: Christoph | D11: Carl | F11: Endri Shameti | G11: Rene
A12: 10 | B12: =B11+7 -> 46190 | C12: Carl | D12: Christoph | F12: Dhruvin | G12: Rene
A13: 11 | B13: =B12+7 -> 46197 | C13: Christoph | D13: Carl | F13: Qiblatain | G13: Rene
A14: 12 | B14: =B13+7 -> 46204 | C14: Carl | D14: Christoph | F14: Vineesh Koppay | G14: Rene
A15: 13 | B15: =B14+7 -> 46211 | C15: Christoph | D15: Carl | F15: Abdul Moeez | G15: Rene
A16: 14 | B16: =B15+7 -> 46218 | C16: Carl | D16: Christoph | F16: Asad Raza | G16: Rene | H16: Demo day!
A17: 15 | B17: =B16+7 -> 46225 | C17: Christoph | D17: Carl | F17: Shikhar | G17: Rene | H17: Retrospective
A19: Product owners, software developers, and Scurm Master are set and ideally don't change over time; the critical part is the Release Manager role you need to define here

Sheet Team Contract
A1: Goals | B1: Create a flawless and valuable project that the industry partner will be able to use. Create clean and reusable code and structures
A3: Meeting norms | B3: - be on time -cams on -reach out if you are not gonna make it
B4: - We'll respect each other's opinions and try to communicate as much as possible
A5: Working norms | B5: - Document and comment your code - We'll use branches in a sensefull way and not work directly on the main branch - Transparency - Clear commit messages - We test our code - We write clean code
A7: Coordination norms | B7: - We'll update the feature board in time - If there are multiple devs working on one item, they will communicate and coordinate and not work independently - We balance the workload among the team
A9: Communication norms | B9: - We talk about issues and problems when we face them - Transparent communication - Daily check the corresponding channels
A11: Consideration norms | B11: - We support each other when ever needed - We talk about issues openly - If we can't reach a consensus, we'll vote - We don't take critique personally
A13: Cont. improvement norms | B13: - We'll be open to learn and teach - We encourage critique and improvements efforts
A15: Rewards | B15: - We celebrate milestones with pizza - Very helpful team members get an extra slice of pizza
A17: Sanctions | B17: - Sit ups (at least 10, more if needed)
A19: Signatures
A21: Scrum Master | B21: Rene Jokiel
A22: Product owner | B22: Christoph Huy
A23: Product owner | B23: Carl Mosler
A24: Software developer | B24: Endri Shameti
A25: Software developer | B25: Dhruvin Vekariya
A26: Software developer | B26: Abdul Moeez
A27: Software developer | B27: Vineesh Koppay
A28: Software developer | B28: Asad Raza
A29: Software developer | B29: Qiblatain Fatima
A30: Software developer | B30: Shikhar Thakur

Sheet Product Goal
A1: Product Vision | B1: Project Mission
A3: Product Vision: TaskOrbit provides a domain-independent framework for building reliable conversational AI agents through declarative workflows and structured agent orchestration. The platform enables organizations to create configurable voice and chat agents that integrate STT, LLMs, TTS, and external APIs into unified conversational workflows. By standardizing conversational automation across different business domains, TaskOrbit helps companies reduce manual effort, streamline internal and external processes, and deploy scalable AI-driven assistants without building custom infrastructure from scratch. | B3: The mission of this project is to create an MVP for a Voice AI Agent platform. Within the given project time-frame, the team is committed to delivering a fully functional conversational interface supporting configurable single-agent and multi-agent workflows. Core functionality will include the integration of STT for user input, a LLM backend for conversational processing and reasoning, agent orchestration capabilities, and TTS for audio output. The primary objective of this project is to provide a reliable and extensible end-to-end conversational system through the integration of these core components.

Sheet Product Glossary
A1: Term | B1: Definition
A2: E2E | B2: End-to-End (Workflow): The complete processing pipeline of a system interaction, starting from user input through internal processing and concluding with the system’s resulting output.
A3: LLM (Large Language Model) | B3: The underlying AI backend used for conversational processing, reasoning, and generating text responses based on user prompts
A4: TTS (Text to Speech) | B4: The technology that converts text into a spoken audio output (e.g. the voice of the agent talking to the user)
A5: STT (Speech to Text) | B5: The technology that converts spoken audio input into a text (e.g., transcribing the spoken input from a user for a LLM)
A6: Latency | B6: The time delay between the end of a user's spoken input and the beginning of the agent's audio response (Roundtrip Time)
A7: Agent | B7: An autonomous entity within the platform configured with a specific persona, logic and context to interact with the user via voice (or text)
A8: Agent Orchestration | B8: The capability of the TaskOrbit framework to coordinate multiple specialized conversational agents within a single workflow to solve tasks
A9: External Tool | B9: An external integration, API or function invoked by the agent to interact with outside services, databases or systems
A10: Internal Tool | B10: An internal capability, native logic or workflow executed within the agent's system to process information or manage tasks
A11: Conversation | B11: A continuous spoken or written dialogue interaction between a user and an agent, focused on achieving specific tasks
A12: User Interruption | B12: The event where a user starts speaking while agent is actively outputting audio, signaling to stop talking and listen to the new input

Sheet Sprint Goals
A1: Sprint # | B1: Sprint goal
A2: 1 | B2: None
A3: =A2+1 -> 2 | B3: None
A4: =A3+1 -> 3 | B4: None
A5: =A4+1 -> 4 | B5: Optional
A6: =A5+1 -> 5 | B6: Persistent Single-Prompt Agent Prototype
A7: =A6+1 -> 6 | B7: Cloud Deployment/Migration & System Robustness
A8: =A7+1 -> 7 | B8: Advance core platform capabilities & foundation for multi-agent workflow orchestration
A9: =A8+1 -> 8 | B9: Refine agent interaction quality, tool integration & production stability
A10: =A9+1 -> 9 | B10: Conditional Multi-Agent Workflows, Unified Processing & External Tool Integration
A11: =A10+1 -> 10 | B11: Open-Source Model Integration & Evaluation Framework
A12: =A11+1 -> 11 | B12: System Hardening & Benchmarking
A13: =A12+1 -> 12 | B13: Performance Optimization & Demo Day Prep
A14: 13 | B14: Handover & Documentation

Sheet Mid-Project Release plan
A1: Sprint | B1: Goal | C1: Feature Name | D1: Est. size | E1: Est. remaining | F1: Real size | G1: Real remaining
A3: Release
A5: Total | D5: =SUM(D8:D14) -> 120 | E5: =D5 -> 120
A7: Sprints
A8: Sprints | E8: Est. remaining | G8: Real remaining
A9: 1 | D9: =SUM(D18:D22) -> 1 | E9: =$D$5 -> 120 | F9: =SUM(F18) -> 1 | G9: =$D$5 -> 120
A10: =A9+1 -> 2 | D10: =SUM(D24:D27) -> 16 | E10: =E9-D9 -> 119 | F10: =SUM(F24:F27) -> 12 | G10: =G9-F9 -> 119
A11: =A10+1 -> 3 | D11: =sum(D30:D35) -> 19 | E11: =E10-D10 -> 103 | F11: =SUM(F30:F34) -> 18 | G11: =G10-F10 -> 107
A12: 4 | D12: =SUM(D36:D41) -> 30 | E12: =E11-D11 -> 84 | F12: =SUM(F36:F41) -> 36 | G12: =G11-F11 -> 89
A13: 5 | D13: =SUM(D43:D49) -> 29 | E13: =E12-D12 -> 54 | F13: =SUM(F43:F49) -> 28 | G13: =G12-F12 -> 53
A14: 6 | D14: =SUM(D51:D59) -> 25 | E14: =E13-D13 -> 25 | F14: =SUM(F51:F59) -> 21 | G14: =G13-F13 -> 25
A16: Features
A18: =A9 -> 1 | B18: None | C18: Design Team Logo #1 | D18: 1 | F18: 1
A24: =A10 -> 2 | B24: None | C24: Initialize Software Bill of Materials #13 | D24: 3 | F24: 2
C25: System Architecture #12 | D25: 5 | F25: 5
C26: First UI Design & Implementation #5 | D26: 5 | F26: 5
C27: Setup Development Environment #17 | D27: 3 | F27: Not Accepted
A30: =A11 -> 3 | B30: None | C30: Setup Development Environment #17 | D30: 3 | F30: 3
C31: Setup LiveKit Infrastructure #26 | D31: 5 | F31: 5
C32: Schema Foundation #6 | D32: 3 | F32: 3
C33: Prepare Build Process Review #22 | D33: 3 | F33: 2
C34: Core Backend Foundation #7 | D34: 5 | F34: 5
A36: 4 | B36: ='Sprint Goals'!B5 -> Optional | C36: CI/CD Pipeline #10 | D36: 5 | F36: 8
C37: Basic Agent Runtime #33 | D37: 5 | F37: 5
C38: Basic LLM Integration #18 | D38: 5 | F38: 5
C39: DB Integration #32 | D39: 5 | F39: 5
C40: Audio Output via LiveKit (Text-to-Speech) # 15 | D40: 5 | F40: 5
C41: Audio Input via LiveKit (Speech-to-Text) #14 | D41: 5 | F41: 8
A43: 5 | B43: ='Sprint Goals'!B6 -> Persistent Single-Prompt Agent Prototype | C43: Build Process Video #43 | D43: 2 | F43: 3
C44: User Conversation History #45 | D44: 5 | F44: Not Accepted
C45: Save Agent Configuration #47 | D45: 3 | F45: 3
C46: Load Agent Configuration #51 | D46: 3 | F46: 3
C47: Manage Agent Configuration #52 | D47: 3 | F47: 3
C48: Logging & Monitoring Setup #11 | D48: 8 | F48: 8
C49: Voice Interruption for Audio Chat #55 | D49: 5 | F49: 8
A51: 6 | B51: ='Sprint Goals'!B7 -> Cloud Deployment/Migration & System Robustness | C51: User Conversation History #45 | D51: 5 | F51: Not Accepted
C52: User, Design & Build Documentation #74 | D52: 2 | F52: 3
C53: Slot Extraction for Structured Task Inputs #70 | D53: 5 | F53: 5
C54: Integrate Cloud Environment with IaC #21 | D54: 8 | F54: 8
C55: Agent Persona Guardrails #69 | D55: 5 | F55: 5
...

Sheet Velocity Tracking
A1: Sprint # | B1: Story Points Realized | C1: Story Points Estimate
A2: 1 | B2: ='Mid-Project Release plan'!F9 -> 1 | C2: {='Mid-Project Release plan'!D9:D14} -> 1
A3: =A2+1 -> 2 | B3: ='Mid-Project Release plan'!F10 -> 12 | C3: 16
A4: =A3+1 -> 3 | B4: ='Mid-Project Release plan'!F11 -> 18 | C4: 19
A5: =A4+1 -> 4 | B5: ='Mid-Project Release plan'!F12 -> 36 | C5: 30
A6: =A5+1 -> 5 | B6: =IF('Mid-Project Release plan'!F13=0, "", 'Mid-Project Release plan'!F13) -> 28 | C6: 29
A7: =A6+1 -> 6 | B7: =IF('Mid-Project Release plan'!F14=0, "", 'Mid-Project Release plan'!F14) -> 21 | C7: 25
A8: =A7+1 -> 7 | B8: =IF('Final Project Release plan'!F9=0, "", 'Final Project Release plan'!F9) -> 30 | C8: =IF('Final Project Release plan'!D9=0, "", 'Final Project Release plan'!D9) -> 30
A9: =A8+1 -> 8 | B9: =IF('Final Project Release plan'!F10=0, "", 'Final Project Release plan'!F10) | C9: =IF(OR('Final Project Release plan'!D10=0, B8=""), "", 'Final Project Release plan'!D10) -> 24
A10: =A9+1 -> 9 | B10: =IF('Final Project Release plan'!F11=0, "", 'Final Project Release plan'!F11) | C10: =IF(OR('Final Project Release plan'!D11=0, B9=""), "", 'Final Project Release plan'!D11)
A11: =A10+1 -> 10 | B11: =IF('Final Project Release plan'!F12=0, "", 'Final Project Release plan'!F12) | C11: =IF(OR('Final Project Release plan'!D12=0, B10=""), "", 'Final Project Release plan'!D12)
A12: =A11+1 -> 11 | B12: =IF('Final Project Release plan'!F13=0, "", 'Final Project Release plan'!F13) | C12: =IF(OR('Final Project Release plan'!D13=0, B11=""), "", 'Final Project Release plan'!D13)
A13: =A12+1 -> 12 | B13: =IF('Final Project Release plan'!F14=0, "", 'Final Project Release plan'!F14) | C13: =IF(OR('Final Project Release plan'!D14=0, B12=""), "", 'Final Project Release plan'!D14)
A14: =A13+1 -> 13 | B14: =IF('Final Project Release plan'!F15=0, "", 'Final Project Release plan'!F15) | C14: =IF(OR('Final Project Release plan'!D15=0, B13=""), "", 'Final Project Release plan'!D15)
A15: =A14+1 -> 14 | B15: =IF('Final Project Release plan'!F16=0, "", 'Final Project Release plan'!F16) | C15: =IF(OR('Final Project Release plan'!D16=0, B14=""), "", 'Final Project Release plan'!D16)
B16: =IF('Final Project Release plan'!F17=0, "", 'Final Project Release plan'!F17)
B18: PLEASE CREATE THE VELOCITY CHART ON A NEW TAB USING THE DATA FROM THIS TAB

Sheet Velocity Chart

Sheet Final Project Release plan
A1: Sprint | B1: Goal | C1: Feature Name | D1: Est. size | E1: Est. remaining | F1: Real size | G1: Real remaining
A3: Release
A5: Total | D5: =sum(D8:D15) -> 167 | E5: =D5 -> 167
A7: Sprints
A8: Sprints | E8: Est. remaining | G8: Real remaining
A9: 7 | D9: =sum(D19:D24) -> 30 | E9: =$D$5 -> 167 | F9: =sum(F19:F24) -> 30 | G9: =$D$5 -> 167
A10: =A9+1 -> 8 | D10: =SUM(D26:D32) -> 24 | E10: =E9-D9 -> 137 | F10: =SUM(F26:F32) -> 0 | G10: =G9-F9 -> 137
A11: =A10+1 -> 9 | D11: =SUM(D34:D40) -> 22 | E11: =E10-D10 -> 113 | F11: =SUM(F34:F40) -> 0 | G11: =G10-F10 -> 137
A12: 10 | D12: =SUM(D41:D47) -> 26 | E12: =E11-D11 -> 91 | F12: =SUM(F41:F47) -> 0 | G12: =G11-F11 -> 137
A13: 11 | D13: =SUM(D49:D54) -> 25 | E13: =E12-D12 -> 65 | F13: =SUM(F49:F55) -> 0 | G13: =G12-F12 -> 137
A14: 12 | D14: =SUM(D57:D63) -> 22 | E14: =E13-D13 -> 40 | F14: =SUM(F57:F63) -> 0 | G14: =G13-F13 -> 137
A15: 13 | D15: =SUM(D65:D72) -> 18 | E15: =E14-D14 -> 18 | F15: =SUM(F65:F72) -> 0 | G15: =G14-F14 -> 137
A17: Features
A19: =A9 -> 7 | B19: ='Sprint Goals'!B8 -> Advance core platform capabilities & foundation for multi-agent workflow orchestration | C19: Agent Config not persistant through text and voice prompts #99 | D19: 3 | F19: 3
C20: Agent/LLM Memory Safeguards #56 | D20: 8 | F20: 8
C21: Voice input splits into multiple bubbles & numbers/symbols are formatted wrong #102 | D21: 5 | F21: 5
C22: Agent Routing Foundation #8 | D22: 8 | F22: 8
C23: [PROD] Agent config not loaded correctly #100 | D23: 3 | F23: 3
C24: Livekit - Session Limit #112 | D24: 3 | F24: 3
A26: =A10 -> 8 | B26: ='Sprint Goals'!B9 -> Refine agent interaction quality, tool integration & production stability | C26: User Conversation History #45 | D26: 5
C27: Generic Adapter for external Tools #66 | D27: 3
C28: Stream LLM Responses #57 | D28: 5
C29: [Tools] End Call #116 | D29: 3
C30: Critical Action Confirmation #49 | D30: 3
C31: Microphone Mute interrupts Agent TTS output #101 | D31: 3
C32: Provider Model Dropdown #87 | D32: 2
A34: =A11 -> 9 | B34: ='Sprint Goals'!B10 -> Conditional Multi-Agent Workflows, Unified Processing & External Tool Integration | C34: Conditional Workflow Engine #71 | D34: 8
C35: [PROD] Grafana Backend Fix #103 | D35: 3
C36: LLM External Tool Execution #44 | D36: 3
C37: Mute Agent Output #107 | D37: 3
C38: Custom Agent Routing #129 | D38: 5
A41: 10 | B41: ='Sprint Goals'!B11 -> Open-Source Model Integration & Evaluation Framework | C41: Cloud Open Source Inference Server #67 | D41: 8
C42: Benchmarking Environment #86 | D42: 8
C43: Grafana OS Model Monitoring integration | D43: 5
C44: Remove Legacy Text Processing Pipeline #126 | D44: 5
A49: 11 | B49: ='Sprint Goals'!B12 -> System Hardening & Benchmarking | C49: Component Benchmarking #68 | D49: 8
C50: Benchmark Grafana Integration | D50: 3
C51: Issue with the greeting message | D51: 2
C52: Prevent chat bubble fragmentation during continuous speech | D52: 2
C53: Issue with the text input (not being connected to the worker) | D53: 5
...

Sheet Definition of Done
A1: # | B1: Feature Definition of Done | C1: Sprint Release Definition of Done | D1: Project Release Definition of Done
B2: General coding standards are met (eg. Formatting, Comments, Logging, no API-Keys in Repo)
B3: Every PR is peer-reviewed by at least one other developer
B4: Documentation is updated (eg. System Architecture, SBOM)
B5: Unit tests for new features have been written
C6: A release candidate representing a functional and verifiable increment over the previous sprint is tagged
C7: Existing features must remain operational and unaffected by the new changes
C8: Sprint release changelog have been written
D9: The system can be built and started from a clean repository checkout
D10: Core workflows are fully integrated and demonstrable end-to-end
D11: All major components are integrated and operational
D12: No critical or blocker defects remain open
D13: Architecture and technical documentation are finalized and updated
D14: SBOM and required project documentation are completed
D15: CI/CD pipeline passes successfully for the release version
D16: Release version is tagged and reproducible
D17: Build and deployment instructions are documented and verified
D18: Source code, documentation, and deliverables are submitted

Sheet Documentation
A1: Type | B1: Link / reference
A2: Team Logo (SVG + PNG) | B2: https://github.com/amosproj/amos2026ss04-taskorbit-conversational-agent/blob/feature/team-logo-design/Deliverables/sprint-01/team-logo.png

Sheet Bill of Materials
A1: # | B1: Context | C1: Name | D1: Version | E1: License | F1: Comment
A2: 1 | B2: python | C2: fastapi | D2: ^0.115.0 | E2: MIT | F2: REST API framework
A3: 2 | B3: python | C3: uvicorn | D3: ^0.32.0 | E3: BSD | F3: ASGI server
A4: 3 | B4: python | C4: pydantic | D4: ^2.9.0 | E4: MIT | F4: Data validation
A5: 4 | B5: python | C5: pydantic-settings | D5: ^2.6.0 | E5: MIT | F5: Settings management
A6: 5 | B6: python | C6: python-dotenv | D6: ^1.0.1 | E6: BSD | F6: Environment config
A7: 6 | B7: python | C7: livekit-agents | D7: ^1.5.0 | E7: Apache-2.0 | F7: Voice agent framework
A8: 7 | B8: python | C8: sqlalchemy | D8: ^2.0.36 | E8: MIT | F8: Database ORM
A9: 8 | B9: python | C9: alembic | D9: ^1.14.0 | E9: MIT | F9: Database migrations
A10: 9 | B10: python | C10: psycopg | D10: ^3.2.0 | E10: LGPL | F10: PostgreSQL driver
A11: 10 | B11: python | C11: structlog | D11: ^24.4.0 | E11: MIT | F11: Structured logging
A12: 11 | B12: python | C12: prometheus-fastapi-instrumentator | D12: ^7.0.0 | E12: ISC | F12: FastAPI middleware for Prometheus metrics
A13: 12 | B13: python | C13: prometheus-client | D13: ^0.22.0 | E13: Apache-2.0 | F13: Official Prometheus instrumentation client
... A31: 30 | B31: python | C31: aiosqlite | D31: ^0.22.1 | E31: MIT | F31: Async SQLite driver for testing

Sheet Planning Poker
A1: ='Project Team'!A1 -> Last Name | B1: ='Project Team'!B1 -> First Name | C1: Value
A2: ='Project Team'!A2 -> Fatima | B2: ='Project Team'!B2 -> Qiblatain | C2: 0 | E2: =average(C2:C10) -> 0 | F2: =if(stdev(C2:C7) > 0,"NOK", "OK") -> OK
A3: ='Project Team'!A3 -> Huy | B3: ='Project Team'!B3 -> Christoph | C3: 0
A4: ='Project Team'!A4 -> Raza | B4: ='Project Team'!B4 -> Asad
A5: ='Project Team'!A5 -> Jokiel | B5: ='Project Team'!B5 -> Rene
A6: ='Project Team'!A6 -> Mosler | B6: ='Project Team'!B6 -> Carl | E6: 0 | F6: No size
A7: ='Project Team'!A7 -> Vineesh | B7: ='Project Team'!B7 -> Koppay | E7: 1 | F7: Trivial size
A8: ='Project Team'!A8 -> Moeez | B8: ='Project Team'!B8 -> Abdul | E8: 2 | F8: Small size
A9: ='Project Team'!A9 -> Thakur | B9: ='Project Team'!B9 -> Shikhar | E9: 3 | F9: Medium size
A10: ='Project Team'!A10 -> Dhruvin | B10: ='Project Team'!B10 -> Vekariya | E10: 5 | F10: Large size
E11: 8 | F11: Very large size
E12: 13 | F12: Too large (size)
A14: How to play planning poker
A16: 1. Everyone type their number into their value field, don't hit return yet
A17: 2. Someone, perhaps a product owner, count down 3.. 2.. 1..
A18: 3. Then, everyone hit return to submit their value

Sheet Calculations
A1: Sprint # | B1: Story Points Realized | C1: ="Average Realized (" & ROUND(AVERAGE(B2:B16), 0) & " SP/s)" -> Average Realized (21 SP/s) | E1: Mid Project Release | F1: Sprint | G1: Goal | H1: Feature Name | I1: Est. size | J1: Est. remaining | K1: Real size | L1: Real remaining | M1: Development Speed
A2: 1 | B2: ='Velocity Tracking'!B2 -> 1 | C2: =AVERAGE($B$2:$B$16) -> 20.857143
A3: =A2+1 -> 2 | B3: ='Velocity Tracking'!B3 -> 12 | C3: =AVERAGE($B$2:$B$16) -> 20.857143 | F3: Release
A4: =A3+1 -> 3 | B4: ='Velocity Tracking'!B4 -> 18 | C4: =AVERAGE($B$2:$B$16) -> 20.857143
A5: =A4+1 -> 4 | B5: ='Velocity Tracking'!B5 -> 36 | C5: =AVERAGE($B$2:$B$16) -> 20.857143 | F5: Total | I5: =SUM(I8:I15) -> 120 | J5: =I5 -> 120 | M5: =I5/6 -> 20
A6: =A5+1 -> 5 | B6: ='Velocity Tracking'!B6 -> 28 | C6: =AVERAGE($B$2:$B$16) -> 20.857143
A7: =A6+1 -> 6 | B7: ='Velocity Tracking'!B7 -> 21 | C7: =AVERAGE($B$2:$B$16) -> 20.857143 | F7: Sprints
A8: =A7+1 -> 7 | B8: ='Velocity Tracking'!B8 -> 30 | C8: =AVERAGE($B$2:$B$16) -> 20.857143 | F8: Sprints | J8: Est. remaining | L8: Real remaining | M8: ="Development Speed (≈" & ROUND(M5, 0) & " SP/s)" -> Development Speed (≈20 SP/s)
A9: =A8+1 -> 8 | B9: ='Velocity Tracking'!B9 | C9: =AVERAGE($B$2:$B$16) -> 20.857143 | F9: 1 | I9: ='Mid-Project Release plan'!D9 -> 1 | J9: ='Mid-Project Release plan'!E9 -> 120 | K9: ='Mid-Project Release plan'!F9 -> 1 | L9: ='Mid-Project Release plan'!G9 -> 120 | M9: =$I$5 -> 120
A10: =A9+1 -> 9 | B10: ='Velocity Tracking'!B10 | C10: =AVERAGE($B$2:$B$16) -> 20.857143 | F10: =F9+1 -> 2 | I10: ='Mid-Project Release plan'!D10 -> 16 | J10: ='Mid-Project Release plan'!E10 -> 119 | K10: ='Mid-Project Release plan'!F10 -> 12 | L10: ='Mid-Project Release plan'!G10 -> 119 | M10: =M9-$M$5 -> 100
A11: =A10+1 -> 10 | B11: ='Velocity Tracking'!B11 | C11: =AVERAGE($B$2:$B$16) -> 20.857143 | F11: =F10+1 -> 3 | I11: ='Mid-Project Release plan'!D11 -> 19 | J11: ='Mid-Project Release plan'!E11 -> 103 | K11: ='Mid-Project Release plan'!F11 -> 18 | L11: ='Mid-Project Release plan'!G11 -> 107 | M11: =M10-$M$5 -> 80
A12: =A11+1 -> 11 | B12: ='Velocity Tracking'!B12 | C12: =AVERAGE($B$2:$B$16) -> 20.857143 | F12: 4 | I12: ='Mid-Project Release plan'!D12 -> 30 | J12: ='Mid-Project Release plan'!E12 -> 84 | K12: ='Mid-Project Release plan'!F12 -> 36 | L12: ='Mid-Project Release plan'!G12 -> 89 | M12: =M11-$M$5 -> 60
A13: =A12+1 -> 12 | B13: ='Velocity Tracking'!B13 | C13: =AVERAGE($B$2:$B$16) -> 20.857143 | F13: 5 | I13: ='Mid-Project Release plan'!D13 -> 29 | J13: ='Mid-Project Release plan'!E13 -> 54 | K13: ='Mid-Project Release plan'!F13 -> 28 | L13: ='Mid-Project Release plan'!G13 -> 53 | M13: =M12-$M$5 -> 40
A14: =A13+1 -> 13 | B14: ='Velocity Tracking'!B14 | C14: =AVERAGE($B$2:$B$16) -> 20.857143 | F14: 6 | I14: ='Mid-Project Release plan'!D14 -> 25 | J14: ='Mid-Project Release plan'!E14 -> 25 | K14: ='Mid-Project Release plan'!F14 -> 21 | L14: ='Mid-Project Release plan'!G14 -> 25 | M14: =M13-$M$5 -> 20
A15: =A14+1 -> 14 | B15: ='Velocity Tracking'!B15 | C15: =AVERAGE($B$2:$B$16) -> 20.857143 | I15: ='Mid-Project Release plan'!D15 | J15: ='Mid-Project Release plan'!E15 | K15: ='Mid-Project Release plan'!F15 | L15: ='Mid-Project Release plan'!G15 | M15: =M14-$M$5 -> 0
E18: Final Release | F18: Sprint | G18: Goal | H18: Feature Name | I18: Est. size | J18: Est. remaining | K18: Real size | L18: Real remaining | M18: Development Speed
F20: Release
F22: Total | I22: =sum(I25:I32) -> 167 | J22: =I22 -> 167 | M22: =I22/7 -> 23.857143
F24: Sprints
J25: Est. remaining | L25: Real remaining | M25: ="Development Speed (≈" & ROUND(M22, 0) & " SP/s)" -> Development Speed (≈24 SP/s)
F26: 7 | I26: ='Final Project Release plan'!D9 -> 30 | J26: ='Final Project Release plan'!E9 -> 167 | K26: ='Final Project Release plan'!F9 -> 30 | L26: ='Final Project Release plan'!G9 -> 167 | M26: =$I$22 -> 167
F27: =F26+1 -> 8 | I27: ='Final Project Release plan'!D10 -> 24 | J27: ='Final Project Release plan'!E10 -> 137 | K27: ='Final Project Release plan'!F10 -> 0 | L27: ='Final Project Release plan'!G10 -> 137 | M27: =M26-$M$22 -> 143.14286
F28: =F27+1 -> 9 | I28: ='Final Project Release plan'!D11 -> 22 | J28: ='Final Project Release plan'!E11 -> 113 | K28: ='Final Project Release plan'!F11 -> 0 | L28: ='Final Project Release plan'!G11 -> 137 | M28: =M27-$M$22 -> 119.28571
F29: 10 | I29: ='Final Project Release plan'!D12 -> 26 | J29: ='Final Project Release plan'!E12 -> 91 | K29: ='Final Project Release plan'!F12 -> 0 | L29: ='Final Project Release plan'!G12 -> 137 | M29: =M28-$M$22 -> 95.428571
F30: 11 | I30: ='Final Project Release plan'!D13 -> 25 | J30: ='Final Project Release plan'!E13 -> 65 | K30: ='Final Project Release plan'!F13 -> 0 | L30: ='Final Project Release plan'!G13 -> 137 | M30: =M29-$M$22 -> 71.571429
F31: 12 | I31: ='Final Project Release plan'!D14 -> 22 | J31: ='Final Project Release plan'!E14 -> 40 | K31: ='Final Project Release plan'!F14 -> 0 | L31: ='Final Project Release plan'!G14 -> 137 | M31: =M30-$M$22 -> 47.714286
F32: 13 | I32: ='Final Project Release plan'!D15 -> 18 | J32: ='Final Project Release plan'!E15 -> 18 | K32: ='Final Project Release plan'!F15 -> 0 | L32: ='Final Project Release plan'!G15 -> 137 | M32: =M31-$M$22 -> 23.857143
